<?xml version="1.0"?>

<robot xmlns:xacro="http://ros.org/wiki/xacro" name="restaurant">

    <material name="grey">
        <color rgba="1 1 1 1" />
    </material>

    <material name="green">
        <color rgba="1 0.3 0.1 1"/>
    </material>

    <material name="blue">
        <color rgba="0.2 0.2 1 1"/>
    </material>

    <material name="black">
        <color rgba="0 0 0 1"/>
    </material>

    <material name="white">
        <color rgba="1 1 1 1" />
    </material>

    <material name="orange">
        <color rgba="1 0.3 0.1 1"/>
    </material>


 
    <!-- Robot base link -->
  <xacro:macro name="robot_base" params="robot_name">
    <link name="${robot_name}_base_link">
      <visual>
        <origin xyz="0 0 0" rpy="0 0 0"/>
        <geometry>
          <box size="0.5 0.5 0.2"/>
        </geometry>
        <material name="blue"/>
      </visual>
    </link>

    <joint name="${robot_name}_base_joint" type="fixed">
      <origin xyz="0 0 0.1" rpy="0 0 0"/>
      <parent link="${robot_name}_base_link"/>
      <child link="${robot_name}_base_footprint"/>
    </joint>

    <link name="${robot_name}_base_footprint">
      <visual>
        <origin xyz="0 0 0" rpy="0 0 0"/>
        <geometry>
          <box size="0.2 0.2 0.1"/>
        </geometry>
        <material name="green"/>
      </visual>
    </link>
  </xacro:macro>

  <!-- Robot arm -->
  <xacro:macro name="robot_arm" params="robot_name side">
    <joint name="${robot_name}_${side}_shoulder_joint" type="revolute">
      <origin xyz="0 0 0.2" rpy="0 0 0"/>
      <parent link="${robot_name}_base_link"/>
      <child link="${robot_name}_${side}_shoulder_link"/>
      <axis xyz="0 0 1"/>
    </joint>

    <link name="${robot_name}_${side}_shoulder_link">
      <visual>
        <origin xyz="0 0 0" rpy="0 0 0"/>
        <geometry>
          <box size="0.1 0.1 0.4"/>
        </geometry>
        <material name="grey"/>
      </visual>
    </link>

    <!-- Add more joints and links for the arm (elbow, wrist, hand) -->

    <joint name="${robot_name}_${side}_elbow_joint" type="revolute">
      <origin xyz="0 0 0.4" rpy="0 0 0"/>
      <parent link="${robot_name}_${side}_shoulder_link"/>
      <child link="${robot_name}_${side}_elbow_link"/>
      <axis xyz="0 0 1"/>
    </joint>

    <link name="${robot_name}_${side}_elbow_link">
      <visual>
        <origin xyz="0 0 0" rpy="0 0 0"/>
        <geometry>
          <box size="0.1 0.1 0.3"/>
        </geometry>
        <material name="grey"/>
      </visual>
    </link>

    <!-- Define wrist, hand, and fingers similarly -->

  </xacro:macro>

  <!-- Camera mount -->
  <xacro:macro name="camera_mount" params="robot_name">
    <link name="${robot_name}_camera_mount">
      <visual>
        <origin xyz="0.1 0 0.2" rpy="0 0 0"/>
        <geometry>
          <box size="0.1 0.1 0.1"/>
        </geometry>
        <material name="black"/>
      </visual>
    </link>

    <joint name="${robot_name}_camera_mount_joint" type="fixed">
      <origin xyz="0 0 0.2" rpy="0 0 0"/>
      <parent link="${robot_name}_base_link"/>
      <child link="${robot_name}_camera_mount"/>
    </joint>

    <!-- Add camera sensor -->
    <xacro:include filename="camera_sensor.xacro"/>
    <xacro:camera_sensor parent="${robot_name}_camera_mount" prefix="${robot_name}_"/>

  </xacro:macro>

  <!-- Sensors (example for a generic sensor) -->
  <xacro:macro name="generic_sensor" params="robot_name">
    <link name="${robot_name}_sensor_link">
      <visual>
        <origin xyz="0.2 0 0.1" rpy="0 0 0"/>
        <geometry>
          <box size="0.05 0.05 0.05"/>
        </geometry>
        <material name="white"/>
      </visual>
    </link>

    <joint name="${robot_name}_sensor_joint" type="fixed">
      <origin xyz="0 0 0.3" rpy="0 0 0"/>
      <parent link="${robot_name}_base_link"/>
      <child link="${robot_name}_sensor_link"/>
    </joint>
  </xacro:macro>

</robot>